<?xml version="1.0" ?>
<robot name="vakra" xmlns:xacro="http://www.ros.org/wiki/xacro">

<xacro:include filename="$(find vakra_description)/urdf/materials.xacro" />
<xacro:include filename="$(find vakra_description)/urdf/vakra.trans" />
<xacro:include filename="$(find vakra_description)/gazebo/vakra_materials.gazebo" />
<xacro:include filename="$(find vakra_description)/gazebo/vakra_physics.gazebo" />
<xacro:include filename="$(find vakra_description)/gazebo/vakra_plugins.gazebo" />

<link name="base_footprint"/>

<link name="base_link">
  <inertial>
    <origin rpy="0 0 0" xyz="0.01651650630396252 -0.039387864784774386 0.2781670624228419"/>
    <mass value="2.379664751421723"/>
    <inertia ixx="0.011528" ixy="-3.2e-05" ixz="-0.000126" iyy="0.017554" iyz="4e-06" izz="0.024797"/>
  </inertial>
  <visual>
    <origin rpy="0 0 0" xyz="0 0 0"/>
    <geometry>
      <mesh filename="package://vakra_description/meshes/base_link.stl" scale="0.001 0.001 0.001"/>
    </geometry>
    <material name="silver"/>
  </visual>
  <collision>
    <origin rpy="0 0 0" xyz="0 0 0"/>
    <geometry>
      <mesh filename="package://vakra_description/meshes/base_link.stl" scale="0.001 0.001 0.001"/>
    </geometry>
  </collision>
</link>

<link name="femur1__1__1">
  <inertial>
    <origin rpy="0 0 0" xyz="-0.024333693559157793 -0.05106487776966842 -0.014045576694845352"/>
    <mass value="1.0823056277172005"/>
    <inertia ixx="0.00269" ixy="-0.000566" ixz="-0.001355" iyy="0.004988" iyz="-0.000327" izz="0.004254"/>
  </inertial>
  <visual>
    <origin rpy="0 0 0" xyz="-0.19536 0.112739 -0.280574"/>
    <geometry>
      <mesh filename="package://vakra_description/meshes/femur1__1__1.stl" scale="0.001 0.001 0.001"/>
    </geometry>
    <material name="silver"/>
  </visual>
  <collision>
    <origin rpy="0 0 0" xyz="-0.19536 0.112739 -0.280574"/>
    <geometry>
      <mesh filename="package://vakra_description/meshes/femur1__1__1.stl" scale="0.001 0.001 0.001"/>
    </geometry>
  </collision>
</link>

<link name="Shoulder1__1__1">
  <inertial>
    <origin rpy="0 0 0" xyz="0.05523873032400456 -0.003595547119901385 4.5635929407650266e-07"/>
    <mass value="0.29461843575635877"/>
    <inertia ixx="0.000442" ixy="-7e-06" ixz="0.0" iyy="0.000747" iyz="0.0" izz="0.000451"/>
  </inertial>
  <visual>
    <origin rpy="0 0 0" xyz="-0.14036 0.094239 -0.280574"/>
    <geometry>
      <mesh filename="package://vakra_description/meshes/Shoulder1__1__1.stl" scale="0.001 0.001 0.001"/>
    </geometry>
    <material name="silver"/>
  </visual>
  <collision>
    <origin rpy="0 0 0" xyz="-0.14036 0.094239 -0.280574"/>
    <geometry>
      <mesh filename="package://vakra_description/meshes/Shoulder1__1__1.stl" scale="0.001 0.001 0.001"/>
    </geometry>
  </collision>
</link>

<link name="femur1_1">
  <inertial>
    <origin rpy="0 0 0" xyz="-0.02433104362846289 0.05106454360242882 -0.014050736146083265"/>
    <mass value="1.0823056277172005"/>
    <inertia ixx="0.00269" ixy="0.000566" ixz="-0.001355" iyy="0.004988" iyz="0.000327" izz="0.004254"/>
  </inertial>
  <visual>
    <origin rpy="0 0 0" xyz="-0.195398 -0.032057 -0.279121"/>
    <geometry>
      <mesh filename="package://vakra_description/meshes/femur1_1.stl" scale="0.001 0.001 0.001"/>
    </geometry>
    <material name="silver"/>
  </visual>
  <collision>
    <origin rpy="0 0 0" xyz="-0.195398 -0.032057 -0.279121"/>
    <geometry>
      <mesh filename="package://vakra_description/meshes/femur1_1.stl" scale="0.001 0.001 0.001"/>
    </geometry>
  </collision>
</link>

<link name="Shoulder1_1">
  <inertial>
    <origin rpy="0 0 0" xyz="0.05523855175032666 0.003595212952661162 9.8001096682232e-08"/>
    <mass value="0.29461843575635877"/>
    <inertia ixx="0.000442" ixy="7e-06" ixz="-0.0" iyy="0.000747" iyz="0.0" izz="0.000451"/>
  </inertial>
  <visual>
    <origin rpy="0 0 0" xyz="-0.140398 -0.013557 -0.279121"/>
    <geometry>
      <mesh filename="package://vakra_description/meshes/Shoulder1_1.stl" scale="0.001 0.001 0.001"/>
    </geometry>
    <material name="silver"/>
  </visual>
  <collision>
    <origin rpy="0 0 0" xyz="-0.140398 -0.013557 -0.279121"/>
    <geometry>
      <mesh filename="package://vakra_description/meshes/Shoulder1_1.stl" scale="0.001 0.001 0.001"/>
    </geometry>
  </collision>
</link>

<link name="femur2__1__1">
  <inertial>
    <origin rpy="0 0 0" xyz="-0.024333693559123293 -0.051064877769666894 -0.014045576694855233"/>
    <mass value="1.0823056277172005"/>
    <inertia ixx="0.00269" ixy="-0.000566" ixz="-0.001355" iyy="0.004988" iyz="-0.000327" izz="0.004254"/>
  </inertial>
  <visual>
    <origin rpy="0 0 0" xyz="0.156378 0.112739 -0.280574"/>
    <geometry>
      <mesh filename="package://vakra_description/meshes/femur2__1__1.stl" scale="0.001 0.001 0.001"/>
    </geometry>
    <material name="silver"/>
  </visual>
  <collision>
    <origin rpy="0 0 0" xyz="0.156378 0.112739 -0.280574"/>
    <geometry>
      <mesh filename="package://vakra_description/meshes/femur2__1__1.stl" scale="0.001 0.001 0.001"/>
    </geometry>
  </collision>
</link>

<link name="Shoulder2__1__1">
  <inertial>
    <origin rpy="0 0 0" xyz="-0.05523808741171643 -0.0035955471198991784 3.583390427164268e-07"/>
    <mass value="0.29461843575635877"/>
    <inertia ixx="0.000442" ixy="7e-06" ixz="0.0" iyy="0.000747" iyz="-0.0" izz="0.000451"/>
  </inertial>
  <visual>
    <origin rpy="0 0 0" xyz="0.101378 0.094239 -0.280574"/>
    <geometry>
      <mesh filename="package://vakra_description/meshes/Shoulder2__1__1.stl" scale="0.001 0.001 0.001"/>
    </geometry>
    <material name="silver"/>
  </visual>
  <collision>
    <origin rpy="0 0 0" xyz="0.101378 0.094239 -0.280574"/>
    <geometry>
      <mesh filename="package://vakra_description/meshes/Shoulder2__1__1.stl" scale="0.001 0.001 0.001"/>
    </geometry>
  </collision>
</link>

<link name="femur2_1">
  <inertial>
    <origin rpy="0 0 0" xyz="-0.024330865054751655 0.051064106620084426 -0.014050475808138785"/>
    <mass value="1.0823056277172005"/>
    <inertia ixx="0.00269" ixy="0.000566" ixz="-0.001355" iyy="0.004988" iyz="0.000327" izz="0.004254"/>
  </inertial>
  <visual>
    <origin rpy="0 0 0" xyz="0.156378 -0.032261 -0.280574"/>
    <geometry>
      <mesh filename="package://vakra_description/meshes/femur2_1.stl" scale="0.001 0.001 0.001"/>
    </geometry>
    <material name="silver"/>
  </visual>
  <collision>
    <origin rpy="0 0 0" xyz="0.156378 -0.032261 -0.280574"/>
    <geometry>
      <mesh filename="package://vakra_description/meshes/femur2_1.stl" scale="0.001 0.001 0.001"/>
    </geometry>
  </collision>
</link>

<link name="Shoulder2_1">
  <inertial>
    <origin rpy="0 0 0" xyz="-0.05523808741171665 0.003594775970317118 4.5635927997667025e-07"/>
    <mass value="0.29461843575635877"/>
    <inertia ixx="0.000442" ixy="-7e-06" ixz="-0.0" iyy="0.000747" iyz="-0.0" izz="0.000451"/>
  </inertial>
  <visual>
    <origin rpy="0 0 0" xyz="0.101378 -0.013761 -0.280574"/>
    <geometry>
      <mesh filename="package://vakra_description/meshes/Shoulder2_1.stl" scale="0.001 0.001 0.001"/>
    </geometry>
    <material name="silver"/>
  </visual>
  <collision>
    <origin rpy="0 0 0" xyz="0.101378 -0.013761 -0.280574"/>
    <geometry>
      <mesh filename="package://vakra_description/meshes/Shoulder2_1.stl" scale="0.001 0.001 0.001"/>
    </geometry>
  </collision>
</link>

<link name="tibia1_1">
  <inertial>
    <origin rpy="0 0 0" xyz="0.05857634983569892 -0.005999928812024283 -0.09016228024464047"/>
    <mass value="0.147939411240314034"/>
    <inertia ixx="0.000245" ixy="-0.0" ixz="0.000131" iyy="0.000323" iyz="0.0" izz="8e-05"/>
  </inertial>
  <visual>
    <origin rpy="0 0 0" xyz="-0.035183 -0.110057 -0.186621"/>
    <geometry>
      <mesh filename="package://vakra_description/meshes/tibia1_1.stl" scale="0.001 0.001 0.001"/>
    </geometry>
    <material name="silver"/>
  </visual>
  <collision>
    <origin rpy="0 0 0" xyz="-0.035183 -0.110057 -0.186621"/>
    <geometry>
      <mesh filename="package://vakra_description/meshes/tibia1_1.stl" scale="0.001 0.001 0.001"/>
    </geometry>
  </collision>
</link>

<link name="tibia2_1">
  <inertial>
    <origin rpy="0 0 0" xyz="0.05857552840935376 -0.0060003657943698 -0.09016201990659753"/>
    <mass value="0.14793941124031404"/>
    <inertia ixx="0.000245" ixy="-0.0" ixz="0.000131" iyy="0.000323" iyz="0.0" izz="8e-05"/>
  </inertial>
  <visual>
    <origin rpy="0 0 0" xyz="0.316592 -0.110261 -0.188074"/>
    <geometry>
      <mesh filename="package://vakra_description/meshes/tibia2_1.stl" scale="0.001 0.001 0.001"/>
    </geometry>
    <material name="silver"/>
  </visual>
  <collision>
    <origin rpy="0 0 0" xyz="0.316592 -0.110261 -0.188074"/>
    <geometry>
      <mesh filename="package://vakra_description/meshes/tibia2_1.stl" scale="0.001 0.001 0.001"/>
    </geometry>
  </collision>
</link>

<link name="tibia2__1__1">
  <inertial>
    <origin rpy="0 0 0" xyz="0.058575528409412825 -0.006000365794369661 -0.0901620199066957"/>
    <mass value="0.14793941124031404"/>
    <inertia ixx="0.000245" ixy="-0.0" ixz="0.000131" iyy="0.000323" iyz="0.0" izz="8e-05"/>
  </inertial>
  <visual>
    <origin rpy="0 0 0" xyz="0.316592 0.178739 -0.188074"/>
    <geometry>
      <mesh filename="package://vakra_description/meshes/tibia2__1__1.stl" scale="0.001 0.001 0.001"/>
    </geometry>
    <material name="silver"/>
  </visual>
  <collision>
    <origin rpy="0 0 0" xyz="0.316592 0.178739 -0.188074"/>
    <geometry>
      <mesh filename="package://vakra_description/meshes/tibia2__1__1.stl" scale="0.001 0.001 0.001"/>
    </geometry>
  </collision>
</link>

<link name="tibia1__1__1">
  <inertial>
    <origin rpy="0 0 0" xyz="0.05857552840939162 -0.006000365794366358 -0.09016201990669247"/>
    <mass value="0.14793941124031403"/>
    <inertia ixx="0.000245" ixy="-0.0" ixz="0.000131" iyy="0.000323" iyz="0.0" izz="8e-05"/>
  </inertial>
  <visual>
    <origin rpy="0 0 0" xyz="-0.035146 0.178739 -0.188074"/>
    <geometry>
      <mesh filename="package://vakra_description/meshes/tibia1__1__1.stl" scale="0.001 0.001 0.001"/>
    </geometry>
    <material name="silver"/>
  </visual>
  <collision>
    <origin rpy="0 0 0" xyz="-0.035146 0.178739 -0.188074"/>
    <geometry>
      <mesh filename="package://vakra_description/meshes/tibia1__1__1.stl" scale="0.001 0.001 0.001"/>
    </geometry>
  </collision>
</link>

<joint name="footprint_to_base_link" type="fixed">
  <parent link="base_footprint"/>
  <child link="base_link"/>
</joint>

<joint name="rff" type="revolute">
  <origin rpy="0 0 0" xyz="0.055 -0.0185 0.0"/>
  <parent link="Shoulder1__1__1"/>
  <child link="femur1__1__1"/>
  <axis xyz="0.0 1.0 0.0"/>
  <limit effort="15.0" lower="-3.0" upper="3.0" velocity="5.0" />
  <dynamics damping="0.7" />
</joint>

<joint name="rfs" type="revolute">
  <origin rpy="0 0 0" xyz="0.14036 -0.094239 0.280574"/>
  <parent link="base_link"/>
  <child link="Shoulder1__1__1"/>
  <axis xyz="1.0 -0.0 -0.0"/>
  <limit effort="15.0" lower="-3.0" upper="3.0" velocity="5.0" />
  <dynamics damping="0.7" />
</joint>

<joint name="lff" type="revolute">
  <origin rpy="0 0 0" xyz="0.055 0.0185 0.0"/>
  <parent link="Shoulder1_1"/>
  <child link="femur1_1"/>
  <axis xyz="-0.0 -2.0 -0.0"/>
  <limit effort="15.0" lower="-3.0" upper="3.0" velocity="5.0" />
  <dynamics damping="0.7" />
</joint>

<joint name="lfs" type="revolute">
  <origin rpy="0 0 0" xyz="0.140398 0.013557 0.279121"/>
  <parent link="base_link"/>
  <child link="Shoulder1_1"/>
  <axis xyz="1.0 0.0 -0.0"/>
  <limit effort="15.0" lower="-3.0" upper="3.0" velocity="5.0" />
  <dynamics damping="0.7" />
</joint>

<joint name="rbf" type="revolute">
  <origin rpy="0 0 0" xyz="-0.055 -0.0185 0.0"/>
  <parent link="Shoulder2__1__1"/>
  <child link="femur2__1__1"/>
  <axis xyz="0.0 1.0 -0.0"/>
  <limit effort="15.0" lower="-3.0" upper="3.0" velocity="5.0" />
  <dynamics damping="0.7" />
</joint>

<joint name="rbs" type="revolute">
  <origin rpy="0 0 0" xyz="-0.101378 -0.094239 0.280574"/>
  <parent link="base_link"/>
  <child link="Shoulder2__1__1"/>
  <axis xyz="1.0 0.0 -0.0"/>
  <limit effort="15.0" lower="-3.0" upper="3.0" velocity="5.0" />
  <dynamics damping="0.7" />
</joint>

<joint name="lbf" type="revolute">
  <origin rpy="0 0 0" xyz="-0.055 0.0185 0.0"/>
  <parent link="Shoulder2_1"/>
  <child link="femur2_1"/>
  <axis xyz="0.0 -2.0 0.0"/>
  <limit effort="15.0" lower="-3.0" upper="3.0" velocity="5.0" />
  <dynamics damping="0.7" />
</joint>

<joint name="lbs" type="revolute">
  <origin rpy="0 0 0" xyz="-0.101378 0.013761 0.280574"/>
  <parent link="base_link"/>
  <child link="Shoulder2_1"/>
  <axis xyz="1.0 0.0 -0.0"/>
  <limit effort="15.0" lower="-3.0" upper="3.0" velocity="5.0" />
  <dynamics damping="0.7" />
</joint>

<joint name="lft" type="revolute">
  <origin rpy="0 0 0" xyz="-0.160215 0.078 -0.0925"/>
  <parent link="femur1_1"/>
  <child link="tibia1_1"/>
  <axis xyz="0.0 -2.0 -0.0"/>
  <limit effort="15.0" lower="-3.0" upper="3.0" velocity="5.0" />
  <dynamics damping="0.7" />
</joint>

<joint name="lbt" type="revolute">
  <origin rpy="0 0 0" xyz="-0.160214 0.078 -0.0925"/>
  <parent link="femur2_1"/>
  <child link="tibia2_1"/>
  <axis xyz="0.0 -2.0 -0.0"/>
  <limit effort="15.0" lower="-3.0" upper="3.0" velocity="5.0" />
  <dynamics damping="0.7" />
</joint>

<joint name="rbt" type="revolute">
  <origin rpy="0 0 0" xyz="-0.160214 -0.066 -0.0925"/>
  <parent link="femur2__1__1"/>
  <child link="tibia2__1__1"/>
  <axis xyz="0.0 -2.0 0.0"/>
  <limit effort="15.0" lower="-3.0" upper="3.0" velocity="5.0" />
  <dynamics damping="0.7" />
</joint>

<joint name="rft" type="revolute">
  <origin rpy="0 0 0" xyz="-0.160214 -0.066 -0.0925"/>
  <parent link="femur1__1__1"/>
  <child link="tibia1__1__1"/>
  <axis xyz="-0.0 -2.0 -0.0"/>
  <limit effort="15.0" lower="-3.0" upper="3.0" velocity="5.0" />
  <dynamics damping="0.7" />
</joint>

</robot>
