<?xml version="1.0" encoding="utf-8"?>
<!-- =================================================================================== -->
<!-- |    This document was autogenerated by xacro from vakra.xacro                    | -->
<!-- |    EDITING THIS FILE BY HAND IS NOT RECOMMENDED                                 | -->
<!-- =================================================================================== -->
<robot name="vakra">
  <material name="silver">
    <color rgba="0.700 0.700 0.700 1.000"/>
  </material>
  <transmission name="rff_tran">
    <type>transmission_interface/SimpleTransmission</type>
    <joint name="rff">
      <hardwareInterface>hardware_interface/EffortJointInterface</hardwareInterface>
    </joint>
    <actuator name="rff_actr">
      <hardwareInterface>hardware_interface/EffortJointInterface</hardwareInterface>
      <mechanicalReduction>1</mechanicalReduction>
    </actuator>
  </transmission>
  <transmission name="rfs_tran">
    <type>transmission_interface/SimpleTransmission</type>
    <joint name="rfs">
      <hardwareInterface>hardware_interface/EffortJointInterface</hardwareInterface>
    </joint>
    <actuator name="rfs_actr">
      <hardwareInterface>hardware_interface/EffortJointInterface</hardwareInterface>
      <mechanicalReduction>1</mechanicalReduction>
    </actuator>
  </transmission>
  <transmission name="lff_tran">
    <type>transmission_interface/SimpleTransmission</type>
    <joint name="lff">
      <hardwareInterface>hardware_interface/EffortJointInterface</hardwareInterface>
    </joint>
    <actuator name="lff_actr">
      <hardwareInterface>hardware_interface/EffortJointInterface</hardwareInterface>
      <mechanicalReduction>1</mechanicalReduction>
    </actuator>
  </transmission>
  <transmission name="lfs_tran">
    <type>transmission_interface/SimpleTransmission</type>
    <joint name="lfs">
      <hardwareInterface>hardware_interface/EffortJointInterface</hardwareInterface>
    </joint>
    <actuator name="lfs_actr">
      <hardwareInterface>hardware_interface/EffortJointInterface</hardwareInterface>
      <mechanicalReduction>1</mechanicalReduction>
    </actuator>
  </transmission>
  <transmission name="rbf_tran">
    <type>transmission_interface/SimpleTransmission</type>
    <joint name="rbf">
      <hardwareInterface>hardware_interface/EffortJointInterface</hardwareInterface>
    </joint>
    <actuator name="rbf_actr">
      <hardwareInterface>hardware_interface/EffortJointInterface</hardwareInterface>
      <mechanicalReduction>1</mechanicalReduction>
    </actuator>
  </transmission>
  <transmission name="rbs_tran">
    <type>transmission_interface/SimpleTransmission</type>
    <joint name="rbs">
      <hardwareInterface>hardware_interface/EffortJointInterface</hardwareInterface>
    </joint>
    <actuator name="rbs_actr">
      <hardwareInterface>hardware_interface/EffortJointInterface</hardwareInterface>
      <mechanicalReduction>1</mechanicalReduction>
    </actuator>
  </transmission>
  <transmission name="lbf_tran">
    <type>transmission_interface/SimpleTransmission</type>
    <joint name="lbf">
      <hardwareInterface>hardware_interface/EffortJointInterface</hardwareInterface>
    </joint>
    <actuator name="lbf_actr">
      <hardwareInterface>hardware_interface/EffortJointInterface</hardwareInterface>
      <mechanicalReduction>1</mechanicalReduction>
    </actuator>
  </transmission>
  <transmission name="lbs_tran">
    <type>transmission_interface/SimpleTransmission</type>
    <joint name="lbs">
      <hardwareInterface>hardware_interface/EffortJointInterface</hardwareInterface>
    </joint>
    <actuator name="lbs_actr">
      <hardwareInterface>hardware_interface/EffortJointInterface</hardwareInterface>
      <mechanicalReduction>1</mechanicalReduction>
    </actuator>
  </transmission>
  <transmission name="lft_tran">
    <type>transmission_interface/SimpleTransmission</type>
    <joint name="lft">
      <hardwareInterface>hardware_interface/EffortJointInterface</hardwareInterface>
    </joint>
    <actuator name="lft_actr">
      <hardwareInterface>hardware_interface/EffortJointInterface</hardwareInterface>
      <mechanicalReduction>1</mechanicalReduction>
    </actuator>
  </transmission>
  <transmission name="lbt_tran">
    <type>transmission_interface/SimpleTransmission</type>
    <joint name="lbt">
      <hardwareInterface>hardware_interface/EffortJointInterface</hardwareInterface>
    </joint>
    <actuator name="lbt_actr">
      <hardwareInterface>hardware_interface/EffortJointInterface</hardwareInterface>
      <mechanicalReduction>1</mechanicalReduction>
    </actuator>
  </transmission>
  <transmission name="rbt_tran">
    <type>transmission_interface/SimpleTransmission</type>
    <joint name="rbt">
      <hardwareInterface>hardware_interface/EffortJointInterface</hardwareInterface>
    </joint>
    <actuator name="rbt_actr">
      <hardwareInterface>hardware_interface/EffortJointInterface</hardwareInterface>
      <mechanicalReduction>1</mechanicalReduction>
    </actuator>
  </transmission>
  <transmission name="rft_tran">
    <type>transmission_interface/SimpleTransmission</type>
    <joint name="rft">
      <hardwareInterface>hardware_interface/EffortJointInterface</hardwareInterface>
    </joint>
    <actuator name="rft_actr">
      <hardwareInterface>hardware_interface/EffortJointInterface</hardwareInterface>
      <mechanicalReduction>1</mechanicalReduction>
    </actuator>
  </transmission>
  <gazebo reference="base_link">
    <material>Gazebo/Black</material>
  </gazebo>
  <gazebo reference="femur1__1__1">
    <material>Gazebo/Blue</material>
  </gazebo>
  <gazebo reference="Shoulder1__1__1">
    <material>Gazebo/Green</material>
  </gazebo>
  <gazebo reference="femur1_1">
    <material>Gazebo/Blue</material>
  </gazebo>
  <gazebo reference="Shoulder1_1">
    <material>Gazebo/Green</material>
  </gazebo>
  <gazebo reference="femur2__1__1">
    <material>Gazebo/Blue</material>
  </gazebo>
  <gazebo reference="Shoulder2__1__1">
    <material>Gazebo/Green</material>
  </gazebo>
  <gazebo reference="femur2_1">
    <material>Gazebo/Blue</material>
  </gazebo>
  <gazebo reference="Shoulder2_1">
    <material>Gazebo/Green</material>
  </gazebo>
  <gazebo reference="tibia1_1">
    <material>Gazebo/Silver</material>
  </gazebo>
  <gazebo reference="tibia2_1">
    <material>Gazebo/Silver</material>
  </gazebo>
  <gazebo reference="tibia2__1__1">
    <material>Gazebo/Silver</material>
  </gazebo>
  <gazebo reference="tibia1__1__1">
    <material>Gazebo/Silver</material>
  </gazebo>
  <gazebo reference="base_link">
    <mu1>0.5</mu1>
    <mu2>0.5</mu2>
    <selfCollide>true</selfCollide>
    <gravity>true</gravity>
  </gazebo>
  <gazebo reference="femur1__1__1">
    <mu1>0.5</mu1>
    <mu2>0.5</mu2>
    <selfCollide>true</selfCollide>
  </gazebo>
  <gazebo reference="Shoulder1__1__1">
    <mu1>0.5</mu1>
    <mu2>0.5</mu2>
    <selfCollide>true</selfCollide>
  </gazebo>
  <gazebo reference="femur1_1">
    <mu1>0.5</mu1>
    <mu2>0.5</mu2>
    <selfCollide>true</selfCollide>
  </gazebo>
  <gazebo reference="Shoulder1_1">
    <mu1>0.5</mu1>
    <mu2>0.5</mu2>
    <selfCollide>true</selfCollide>
  </gazebo>
  <gazebo reference="femur2__1__1">
    <mu1>0.5</mu1>
    <mu2>0.5</mu2>
    <selfCollide>true</selfCollide>
  </gazebo>
  <gazebo reference="Shoulder2__1__1">
    <mu1>0.5</mu1>
    <mu2>0.5</mu2>
    <selfCollide>true</selfCollide>
  </gazebo>
  <gazebo reference="femur2_1">
    <mu1>0.5</mu1>
    <mu2>0.5</mu2>
    <selfCollide>true</selfCollide>
  </gazebo>
  <gazebo reference="Shoulder2_1">
    <mu1>0.5</mu1>
    <mu2>0.5</mu2>
    <selfCollide>true</selfCollide>
  </gazebo>
  <gazebo reference="tibia1_1">
    <mu1>200</mu1>
    <mu2>200</mu2>
    <selfCollide>true</selfCollide>
  </gazebo>
  <gazebo reference="tibia2_1">
    <mu1>200</mu1>
    <mu2>200</mu2>
    <selfCollide>true</selfCollide>
  </gazebo>
  <gazebo reference="tibia2__1__1">
    <mu1>200</mu1>
    <mu2>200</mu2>
    <selfCollide>true</selfCollide>
  </gazebo>
  <gazebo reference="tibia1__1__1">
    <mu1>200</mu1>
    <mu2>200</mu2>
    <selfCollide>true</selfCollide>
  </gazebo>
  <gazebo>
    <plugin filename="libgazebo_ros_control.so" name="control">
      <robotNamespace>/vakra</robotNamespace>
    </plugin>
  </gazebo>
  <link name="base_link">
    <inertial>
      <origin rpy="0 0 0" xyz="0.01651650630396252 -0.039387864784774386 0.2781670624228419"/>
      <mass value="2.379664751421723"/>
      <inertia ixx="0.011528" ixy="-3.2e-05" ixz="-0.000126" iyy="0.017554" iyz="4e-06" izz="0.024797"/>
    </inertial>
    <visual>
      <origin rpy="0 0 0" xyz="0 0 0"/>
      <geometry>
        <mesh filename="package://vakra_description/meshes/base_link.stl" scale="0.001 0.001 0.001"/>
      </geometry>
      <material name="silver"/>
    </visual>
    <collision>
      <origin rpy="0 0 0" xyz="0 0 0"/>
      <geometry>
        <mesh filename="package://vakra_description/meshes/base_link.stl" scale="0.001 0.001 0.001"/>
      </geometry>
    </collision>
  </link>
  <link name="femur1__1__1">
    <inertial>
      <origin rpy="0 0 0" xyz="-0.024333693559157793 -0.05106487776966842 -0.014045576694845352"/>
      <mass value="1.0823056277172005"/>
      <inertia ixx="0.00269" ixy="-0.000566" ixz="-0.001355" iyy="0.004988" iyz="-0.000327" izz="0.004254"/>
    </inertial>
    <visual>
      <origin rpy="0 0 0" xyz="-0.19536 0.112739 -0.280574"/>
      <geometry>
        <mesh filename="package://vakra_description/meshes/femur1__1__1.stl" scale="0.001 0.001 0.001"/>
      </geometry>
      <material name="silver"/>
    </visual>
    <collision>
      <origin rpy="0 0 0" xyz="-0.19536 0.112739 -0.280574"/>
      <geometry>
        <mesh filename="package://vakra_description/meshes/femur1__1__1.stl" scale="0.001 0.001 0.001"/>
      </geometry>
    </collision>
  </link>
  <link name="Shoulder1__1__1">
    <inertial>
      <origin rpy="0 0 0" xyz="0.05523873032400456 -0.003595547119901385 4.5635929407650266e-07"/>
      <mass value="0.29461843575635877"/>
      <inertia ixx="0.000442" ixy="-7e-06" ixz="0.0" iyy="0.000747" iyz="0.0" izz="0.000451"/>
    </inertial>
    <visual>
      <origin rpy="0 0 0" xyz="-0.14036 0.094239 -0.280574"/>
      <geometry>
        <mesh filename="package://vakra_description/meshes/Shoulder1__1__1.stl" scale="0.001 0.001 0.001"/>
      </geometry>
      <material name="silver"/>
    </visual>
    <collision>
      <origin rpy="0 0 0" xyz="-0.14036 0.094239 -0.280574"/>
      <geometry>
        <mesh filename="package://vakra_description/meshes/Shoulder1__1__1.stl" scale="0.001 0.001 0.001"/>
      </geometry>
    </collision>
  </link>
  <link name="femur1_1">
    <inertial>
      <origin rpy="0 0 0" xyz="-0.02433104362846289 0.05106454360242882 -0.014050736146083265"/>
      <mass value="1.0823056277172005"/>
      <inertia ixx="0.00269" ixy="0.000566" ixz="-0.001355" iyy="0.004988" iyz="0.000327" izz="0.004254"/>
    </inertial>
    <visual>
      <origin rpy="0 0 0" xyz="-0.195398 -0.032057 -0.279121"/>
      <geometry>
        <mesh filename="package://vakra_description/meshes/femur1_1.stl" scale="0.001 0.001 0.001"/>
      </geometry>
      <material name="silver"/>
    </visual>
    <collision>
      <origin rpy="0 0 0" xyz="-0.195398 -0.032057 -0.279121"/>
      <geometry>
        <mesh filename="package://vakra_description/meshes/femur1_1.stl" scale="0.001 0.001 0.001"/>
      </geometry>
    </collision>
  </link>
  <link name="Shoulder1_1">
    <inertial>
      <origin rpy="0 0 0" xyz="0.05523855175032666 0.003595212952661162 9.8001096682232e-08"/>
      <mass value="0.29461843575635877"/>
      <inertia ixx="0.000442" ixy="7e-06" ixz="-0.0" iyy="0.000747" iyz="0.0" izz="0.000451"/>
    </inertial>
    <visual>
      <origin rpy="0 0 0" xyz="-0.140398 -0.013557 -0.279121"/>
      <geometry>
        <mesh filename="package://vakra_description/meshes/Shoulder1_1.stl" scale="0.001 0.001 0.001"/>
      </geometry>
      <material name="silver"/>
    </visual>
    <collision>
      <origin rpy="0 0 0" xyz="-0.140398 -0.013557 -0.279121"/>
      <geometry>
        <mesh filename="package://vakra_description/meshes/Shoulder1_1.stl" scale="0.001 0.001 0.001"/>
      </geometry>
    </collision>
  </link>
  <link name="femur2__1__1">
    <inertial>
      <origin rpy="0 0 0" xyz="-0.024333693559123293 -0.051064877769666894 -0.014045576694855233"/>
      <mass value="1.0823056277172005"/>
      <inertia ixx="0.00269" ixy="-0.000566" ixz="-0.001355" iyy="0.004988" iyz="-0.000327" izz="0.004254"/>
    </inertial>
    <visual>
      <origin rpy="0 0 0" xyz="0.156378 0.112739 -0.280574"/>
      <geometry>
        <mesh filename="package://vakra_description/meshes/femur2__1__1.stl" scale="0.001 0.001 0.001"/>
      </geometry>
      <material name="silver"/>
    </visual>
    <collision>
      <origin rpy="0 0 0" xyz="0.156378 0.112739 -0.280574"/>
      <geometry>
        <mesh filename="package://vakra_description/meshes/femur2__1__1.stl" scale="0.001 0.001 0.001"/>
      </geometry>
    </collision>
  </link>
  <link name="Shoulder2__1__1">
    <inertial>
      <origin rpy="0 0 0" xyz="-0.05523808741171643 -0.0035955471198991784 3.583390427164268e-07"/>
      <mass value="0.29461843575635877"/>
      <inertia ixx="0.000442" ixy="7e-06" ixz="0.0" iyy="0.000747" iyz="-0.0" izz="0.000451"/>
    </inertial>
    <visual>
      <origin rpy="0 0 0" xyz="0.101378 0.094239 -0.280574"/>
      <geometry>
        <mesh filename="package://vakra_description/meshes/Shoulder2__1__1.stl" scale="0.001 0.001 0.001"/>
      </geometry>
      <material name="silver"/>
    </visual>
    <collision>
      <origin rpy="0 0 0" xyz="0.101378 0.094239 -0.280574"/>
      <geometry>
        <mesh filename="package://vakra_description/meshes/Shoulder2__1__1.stl" scale="0.001 0.001 0.001"/>
      </geometry>
    </collision>
  </link>
  <link name="femur2_1">
    <inertial>
      <origin rpy="0 0 0" xyz="-0.024330865054751655 0.051064106620084426 -0.014050475808138785"/>
      <mass value="1.0823056277172005"/>
      <inertia ixx="0.00269" ixy="0.000566" ixz="-0.001355" iyy="0.004988" iyz="0.000327" izz="0.004254"/>
    </inertial>
    <visual>
      <origin rpy="0 0 0" xyz="0.156378 -0.032261 -0.280574"/>
      <geometry>
        <mesh filename="package://vakra_description/meshes/femur2_1.stl" scale="0.001 0.001 0.001"/>
      </geometry>
      <material name="silver"/>
    </visual>
    <collision>
      <origin rpy="0 0 0" xyz="0.156378 -0.032261 -0.280574"/>
      <geometry>
        <mesh filename="package://vakra_description/meshes/femur2_1.stl" scale="0.001 0.001 0.001"/>
      </geometry>
    </collision>
  </link>
  <link name="Shoulder2_1">
    <inertial>
      <origin rpy="0 0 0" xyz="-0.05523808741171665 0.003594775970317118 4.5635927997667025e-07"/>
      <mass value="0.29461843575635877"/>
      <inertia ixx="0.000442" ixy="-7e-06" ixz="-0.0" iyy="0.000747" iyz="-0.0" izz="0.000451"/>
    </inertial>
    <visual>
      <origin rpy="0 0 0" xyz="0.101378 -0.013761 -0.280574"/>
      <geometry>
        <mesh filename="package://vakra_description/meshes/Shoulder2_1.stl" scale="0.001 0.001 0.001"/>
      </geometry>
      <material name="silver"/>
    </visual>
    <collision>
      <origin rpy="0 0 0" xyz="0.101378 -0.013761 -0.280574"/>
      <geometry>
        <mesh filename="package://vakra_description/meshes/Shoulder2_1.stl" scale="0.001 0.001 0.001"/>
      </geometry>
    </collision>
  </link>
  <link name="tibia1_1">
    <inertial>
      <origin rpy="0 0 0" xyz="0.05857634983569892 -0.005999928812024283 -0.09016228024464047"/>
      <mass value="0.147939411240314034"/>
      <inertia ixx="0.000245" ixy="-0.0" ixz="0.000131" iyy="0.000323" iyz="0.0" izz="8e-05"/>
    </inertial>
    <visual>
      <origin rpy="0 0 0" xyz="-0.035183 -0.110057 -0.186621"/>
      <geometry>
        <mesh filename="package://vakra_description/meshes/tibia1_1.stl" scale="0.001 0.001 0.001"/>
      </geometry>
      <material name="silver"/>
    </visual>
    <collision>
      <origin rpy="0 0 0" xyz="-0.035183 -0.110057 -0.186621"/>
      <geometry>
        <mesh filename="package://vakra_description/meshes/tibia1_1.stl" scale="0.001 0.001 0.001"/>
      </geometry>
    </collision>
  </link>
  <link name="tibia2_1">
    <inertial>
      <origin rpy="0 0 0" xyz="0.05857552840935376 -0.0060003657943698 -0.09016201990659753"/>
      <mass value="0.14793941124031404"/>
      <inertia ixx="0.000245" ixy="-0.0" ixz="0.000131" iyy="0.000323" iyz="0.0" izz="8e-05"/>
    </inertial>
    <visual>
      <origin rpy="0 0 0" xyz="0.316592 -0.110261 -0.188074"/>
      <geometry>
        <mesh filename="package://vakra_description/meshes/tibia2_1.stl" scale="0.001 0.001 0.001"/>
      </geometry>
      <material name="silver"/>
    </visual>
    <collision>
      <origin rpy="0 0 0" xyz="0.316592 -0.110261 -0.188074"/>
      <geometry>
        <mesh filename="package://vakra_description/meshes/tibia2_1.stl" scale="0.001 0.001 0.001"/>
      </geometry>
    </collision>
  </link>
  <link name="tibia2__1__1">
    <inertial>
      <origin rpy="0 0 0" xyz="0.058575528409412825 -0.006000365794369661 -0.0901620199066957"/>
      <mass value="0.14793941124031404"/>
      <inertia ixx="0.000245" ixy="-0.0" ixz="0.000131" iyy="0.000323" iyz="0.0" izz="8e-05"/>
    </inertial>
    <visual>
      <origin rpy="0 0 0" xyz="0.316592 0.178739 -0.188074"/>
      <geometry>
        <mesh filename="package://vakra_description/meshes/tibia2__1__1.stl" scale="0.001 0.001 0.001"/>
      </geometry>
      <material name="silver"/>
    </visual>
    <collision>
      <origin rpy="0 0 0" xyz="0.316592 0.178739 -0.188074"/>
      <geometry>
        <mesh filename="package://vakra_description/meshes/tibia2__1__1.stl" scale="0.001 0.001 0.001"/>
      </geometry>
    </collision>
  </link>
  <link name="tibia1__1__1">
    <inertial>
      <origin rpy="0 0 0" xyz="0.05857552840939162 -0.006000365794366358 -0.09016201990669247"/>
      <mass value="0.14793941124031403"/>
      <inertia ixx="0.000245" ixy="-0.0" ixz="0.000131" iyy="0.000323" iyz="0.0" izz="8e-05"/>
    </inertial>
    <visual>
      <origin rpy="0 0 0" xyz="-0.035146 0.178739 -0.188074"/>
      <geometry>
        <mesh filename="package://vakra_description/meshes/tibia1__1__1.stl" scale="0.001 0.001 0.001"/>
      </geometry>
      <material name="silver"/>
    </visual>
    <collision>
      <origin rpy="0 0 0" xyz="-0.035146 0.178739 -0.188074"/>
      <geometry>
        <mesh filename="package://vakra_description/meshes/tibia1__1__1.stl" scale="0.001 0.001 0.001"/>
      </geometry>
    </collision>
  </link>
  <joint name="rff" type="revolute">
    <origin rpy="0 0 0" xyz="0.055 -0.0185 0.0"/>
    <parent link="Shoulder1__1__1"/>
    <child link="femur1__1__1"/>
    <axis xyz="0.0 1.0 0.0"/>
    <limit effort="15.0" lower="-2.0" upper="2.0" velocity="2.0"/>
    <dynamics damping="0.7"/>
  </joint>
  <joint name="rfs" type="revolute">
    <origin rpy="0 0 0" xyz="0.14036 -0.094239 0.280574"/>
    <parent link="base_link"/>
    <child link="Shoulder1__1__1"/>
    <axis xyz="1.0 -0.0 -0.0"/>
    <limit effort="15.0" lower="-2.0" upper="2.0" velocity="2.0"/>
    <dynamics damping="0.7"/>
  </joint>
  <joint name="lff" type="revolute">
    <origin rpy="0 0 0" xyz="0.055 0.0185 0.0"/>
    <parent link="Shoulder1_1"/>
    <child link="femur1_1"/>
    <axis xyz="-0.0 -2.0 -0.0"/>
    <limit effort="15.0" lower="-2.0" upper="2.0" velocity="2.0"/>
    <dynamics damping="0.7"/>
  </joint>
  <joint name="lfs" type="revolute">
    <origin rpy="0 0 0" xyz="0.140398 0.013557 0.279121"/>
    <parent link="base_link"/>
    <child link="Shoulder1_1"/>
    <axis xyz="1.0 0.0 -0.0"/>
    <limit effort="15.0" lower="-2.0" upper="2.0" velocity="2.0"/>
    <dynamics damping="0.7"/>
  </joint>
  <joint name="rbf" type="revolute">
    <origin rpy="0 0 0" xyz="-0.055 -0.0185 0.0"/>
    <parent link="Shoulder2__1__1"/>
    <child link="femur2__1__1"/>
    <axis xyz="0.0 1.0 -0.0"/>
    <limit effort="15.0" lower="-2.0" upper="2.0" velocity="2.0"/>
    <dynamics damping="0.7"/>
  </joint>
  <joint name="rbs" type="revolute">
    <origin rpy="0 0 0" xyz="-0.101378 -0.094239 0.280574"/>
    <parent link="base_link"/>
    <child link="Shoulder2__1__1"/>
    <axis xyz="1.0 0.0 -0.0"/>
    <limit effort="15.0" lower="-2.0" upper="2.0" velocity="2.0"/>
    <dynamics damping="0.7"/>
  </joint>
  <joint name="lbf" type="revolute">
    <origin rpy="0 0 0" xyz="-0.055 0.0185 0.0"/>
    <parent link="Shoulder2_1"/>
    <child link="femur2_1"/>
    <axis xyz="0.0 -2.0 0.0"/>
    <limit effort="15.0" lower="-2.0" upper="2.0" velocity="2.0"/>
    <dynamics damping="0.7"/>
  </joint>
  <joint name="lbs" type="revolute">
    <origin rpy="0 0 0" xyz="-0.101378 0.013761 0.280574"/>
    <parent link="base_link"/>
    <child link="Shoulder2_1"/>
    <axis xyz="1.0 0.0 -0.0"/>
    <limit effort="15.0" lower="-2.0" upper="2.0" velocity="2.0"/>
    <dynamics damping="0.7"/>
  </joint>
  <joint name="lft" type="revolute">
    <origin rpy="0 0 0" xyz="-0.160215 0.078 -0.0925"/>
    <parent link="femur1_1"/>
    <child link="tibia1_1"/>
    <axis xyz="0.0 -2.0 -0.0"/>
    <limit effort="15.0" lower="-2.0" upper="2.0" velocity="2.0"/>
    <dynamics damping="0.7"/>
  </joint>
  <joint name="lbt" type="revolute">
    <origin rpy="0 0 0" xyz="-0.160214 0.078 -0.0925"/>
    <parent link="femur2_1"/>
    <child link="tibia2_1"/>
    <axis xyz="0.0 -2.0 -0.0"/>
    <limit effort="15.0" lower="-2.0" upper="2.0" velocity="2.0"/>
    <dynamics damping="0.7"/>
  </joint>
  <joint name="rbt" type="revolute">
    <origin rpy="0 0 0" xyz="-0.160214 -0.066 -0.0925"/>
    <parent link="femur2__1__1"/>
    <child link="tibia2__1__1"/>
    <axis xyz="0.0 -2.0 0.0"/>
    <limit effort="15.0" lower="-2.0" upper="2.0" velocity="2.0"/>
    <dynamics damping="0.7"/>
  </joint>
  <joint name="rft" type="revolute">
    <origin rpy="0 0 0" xyz="-0.160214 -0.066 -0.0925"/>
    <parent link="femur1__1__1"/>
    <child link="tibia1__1__1"/>
    <axis xyz="-0.0 -2.0 -0.0"/>
    <limit effort="15.0" lower="-2.0" upper="2.0" velocity="2.0"/>
    <dynamics damping="0.7"/>
  </joint>
</robot>
